Workbook

Sheet SNAPSHOT
C5: Cockburn Sound Data Summary | E5: Last Updated: 22/9/2025
C6: Agency | D6: Program / Dataset | E6: Description | F6: Category | G6: Date range | H6: No. sites | J6: Available in data-lake | K6: Available in data-warehouse | L6: Date last imported | M6: Note
C8: AIMS | D8: TEMP | E8: Temperature Logger Program | F8: PHYSCHEM | G8: 5/2012 - 12/2016 | H8: 5 | J8: Y | K8: Y | L8: 45855
C10: BMT | D10: BNA | E10: Breakwater model output | F10: HYDRO | G10: 1/2011 - 07/2021 | H10: 3 | J10: Y | K10: N
C11: BMT | D11: SWAN | E11: SWAN model export | F11: HYDRO | G11: 1/2013 - 1/2014 | H11: 20 | J11: Y | K11: Y | L11: 45855
C13: BOM | D13: BARRA | E13: Gridded reanalysis export | F13: MET | G13: 10/2010 - 1/2016 | H13: 25 | J13: Y | K13: Y (10/2010 - 2/2012) | L13: 45855 | M13: includes sites from BOM, DPIRD, UWA, WWMSP5
C14: BOM | D14: IDO | E14: Hillary’s tide station | F14: HYDRO | G14: 1/2021 - 5/2023 | H14: 1 | J14: Y | K14: N
C15: BOM | D15: IDY | E15: Weather stations | F15: MET | G15: 1/1985 - 5/2022 | H15: 15 | J15: Y | K15: Y | L15: 45855
C16: BOM | D16: NGIS | E16: Groundwater data | F16: HYDRO | G16: 6/1961 - 8/2020 | H16: TBC | J16: Y | K16: N
C17: BOM | D17: RAIN | E17: Rainfall stations | F17: MET | G17: 1/1944 - 10/2022 | H17: 11 | J17: Y | K17: N
C19: CSIRO | D19: SRFME | E19: Two Rocks transect hydro monitoring | F19: HYDRO | G19: 7/2004 - 7/2005 | H19: 3 | J19: Y | K19: Y | L19: 45855
C20: CSIRO | D20: DALSENO | E20: CS13 bottom O2 monitoring sensor (*) | F20: PHYSCHEM | G20: 10/2018 - 8/2019 | H20: 1 | J20: Y | K20: N
C21: CSIRO | D21: ECKLONIA | E21: Estimated biomass data | F21: BENTHIC | G21: 3/1979 - 3/1981 | H21: 2 | J21: Y | K21: N
C22: CSIRO | D22: FILTERFEEDER | E22: Estimated biomass data | F22: BENTHIC | G22: 9/1994 | H22: 5 | J22: Y | K22: N
C24: CSMC | D24: WQ | E24: CSMC data from MAFRL | F24: PHYSCHEM, NUTRIENT | G24: 11/1982 - 3/2020 | H24: 23 | J24: Y | K24: Y (dates different to data lake) | L24: 45855
C25: CSMC | D25: SG | E25: Seagrass occurrence data | F25: BENTHIC | G25: 2003 - 2022 | H25: 58 | J25: Y | K25: N
C27: DEP | D27: SMCWS | E27: South Metropolitan Coastal Waters Study WQ data (*) | F27: PHYSCHEM, NUTRIENT | G27: 1/1991 - 3/1994 | H27: 23 | J27: Y | K27: Y | L27: 45855
C29: DOT | D29: AWAC | E29: DOT AWAC stations | F29: HYDRO | G29: 6/2008 - 12/2009 | H29: 6 | J29: Y | K29: N
C30: DOT | D30: TIDE | E30: DOT tide stations | F30: HYDRO | G30: 2/1986 - 12/2023 | H30: 4 | J30: Y | K30: Y (dates different to data lake) | L30: 45855
C31: DOT | D31: WAVE | E31: DOT wave buoys | F31: HYDRO | G31: varies | H31: 6 | J31: Y | K31: N
C33: DPIRD | D33: CRP | E33: Crab Research Program | F33: PHYSCHEM | G33: 2007 - 2015 | H33: 3 | J33: Y | K33: Y | L33: 45855
C35: DWER | D35: BORE | E35: Groundwater monitoring | F35: HYDRO | G35: 10/2018 - 5/2022 | H35: 1 | J35: Y | K35: N
C36: DWER | D36: CSMC-phy | E36: Phytoplankton taxonomy | F36: PLANKTON | G36: 3/2019 - 11/2022 | H36: 25 | J36: Y | K36: Y | L36: 45855
C37: DWER | D37: CSMC-wq | E37: CSMC data via WIR | F37: PHYSCHEM, NUTRIENT | G37: 01/1991 - 6/2023 | H37: TBC | J37: Y | K37: Y | L37: 46053 | M37: Applied a one‑off conversion factor (×2.3026) directly to existing DWER CSMWQ CSVs for Light Attenuation Coefficient (var00216) in data-warehouse/csv/dwer/csmwq. The pipeline is not working properly and still needs troubleshooting
C38: DWER | D38: CSMOORING-WQA | E38: WQ mooring deployments, incl spectral light | F38: LIGHT | G38: 9/2021 - 2/2022 | H38: 8 | J38: Y | K38: Y (dates different to data lake) | L38: 46063
C39: DWER | D39: CSMOORING-WQB | E39: WQB mooring deployments | F39: PHYSCHEM, NUTRIENT | G39: 03/2022-12/2024 | H39: 10 | J39: Y | K39: N
C40: DWER | D40: CSMOORING-WQC | E40: WQ mooring deployments, incl spectral light | F40: LIGHT | G40: 07/2022-08/2022 | H40: 2 | J40: Y | K40: Y | L40: 46058
C41: DWER | D41: CSMOORING-MS9D | E41: WQ mooring deployments, incl spectral light | F41: LIGHT | G41: 08/2023-08/2025 | H41: 1 | J41: Y | K41: Y | L41: 46058
C42: DWER | D42: SCE-phy | E42: Phytoplankton taxonomy | F42: PLANKTON | G42: 2012 - 2020 | H42: 29 | J42: Y | K42: N
C43: DWER | D43: SCE-est | E43: Estuary monitoring | F43: PHYSCHEM, NUTRIENT | G43: 3/2005 - 7/2024 | H43: TBC | J43: Y | K43: Y | L43: 45855
C45: ESA | D45: GC-Optics | E45: GlobColor ocean color satellite exports | F45: LIGHT | G45: 9/1997 - 10/2024 | H45: 13 | J45: Y | K45: Y | L45: 45855
C46: ESA | D46: GC-Plankton | F46: PLANKTON | G46: 9/1997 - 10/2024 | H46: 13 | J46: Y | K46: Y | L46: 45855
C47: ESA | D47: GC-PP | F47: PLANKTON | G47: 9/1997 - 10/2024 | H47: 13 | J47: Y | K47: Y | L47: 45855
C48: ESA | D48: GC-Reflectance | F48: LIGHT | G48: 9/1997 - 10/2024 | H48: 13 | J48: Y | K48: Y | L48: 45855
C49: ESA | D49: GC-Transp | F49: PHYSCHEM | G49: 9/1997 - 10/2024 | H49: 13 | J49: Y | K49: Y | L49: 45855
C50: ESA | D50: SEN-NC | E50: Sentinel satellite exports | F50: PHYSCHEM | G50: 5/2016 - 10/2024 | H50: 32 | J50: Y | K50: Y | L50: 45855
C52: FPA | D52: MQMP | E52: Marine Quality Monitoring Program | F52: PHYSCHEM, NUTRIENT | G52: 3/2002 - 1/2021 | H52: 30 | J52: Y | K52: Y | L52: 45855
C53: FPA | D53: TIDE | E53: Tidal stations | F53: HYDRO | G53: 2011 - 2016 | H53: 2 | J53: Y | K53: N
C55: GA | D55: SKENE | E55: Skene et al sediment survey | F55: SEDIMENT | J55: N | K55: N
C57: IMOS | D57: AMNM | E57: Rottnest IMOS mooring data | F57: HYDRO | G57: 7/2017 - 4/2022 | H57: 2 | J57: Y | K57: Y | L57: 45855
...

Sheet KEY
B3: Data Imported into a standard format in the warehouse
B4: Data recieved, awaiting import in the lake
B5: Data not received, High Priority
B6: Data not received, Medium Priority
B7: Data not received, Low Priority
B8: Data not requested

Sheet INFO
E1: CSIEM category | I1: Data Classification
A2: Ongoing | C2: Action Required | E2: Bathymetry | G2: High | I2: MET General | J2: General weather data, including AT, RH, Wind, and/or Clouds
A3: Fixed | C3: Data Lake | E3: Meteorology | G3: Medium | I3: MET Wind | J3: Wind data
C4: Data Warehouse | E4: Hydrodynamics | G4: Low | I4: MET Solar | J4: Solar data
C5: Finalised | E5: Biota benthic | I5: HYDRO Level | J5: Water level data
E6: Sediment | I6: HYDRO Flow | J6: Water flow data
E7: Discharge | I7: HYDRO Wave | J7: Wave data
E8: Stormwater | I8: HYDRO Velocity | J8: Velocity data, e.g. from ADV or ADCP
E9: Groundwater | I9: WQ Grab | J9: WQ sample taken for laboratory analysis, e.g., nutrients
E10: Operational | I10: WQ Sensor | J10: WQ sensor deployed at a fixed position
E11: Knowledge | I11: WQ Profile | J11: WQ profiles
E12: Hydrology | I12: WQ Image | J12: WQ image from satellite or remote vehicle
E13: Water quality sensor | I13: SED Grab | J13: Data taken from a sediment core or grab
E14: Water quality profile grab | I14: SED Flux | J14: Sediment flux data, from core or bethic chamber
E15: Biota pelagic | I15: SED Profile | J15: Sediment profile data (e.g., porewater)
I16: ECO Benthic | J16: Benthic biomass or species abundance, incl life cycle data, e.g., seagrass biomass
I17: ECO Pelagic | J17: Pelagic biomass or species abundance, incl life cycle data, e.g., phytoplankton
I18: ECO Flux | J18: Biological flux such as in situ uptake rate, e.g. photosynthesis, respiration
I19: MIXED | J19: Data is a mixture of above categories
I20: UNCLASSIFIED | J20: Data yet to be classififed
I21: BATHYMETRY | J21: Bathymetric data

Sheet WEATHER
A1: PLANKTON
A2: METEOROLOGY | B2: Agency | C2: Variable | D2: #Sites | E2: Site Names | F2: Data Location | G2: Data Origin | H2: References / Further Information | I2: Master catalogue row# | J2: NOTES
B3: WEATHER STATIONS
A5: BOM-IDY | B5: BOM | C5: Weather vars | D5: 15 | E5: Garden Island, Swanbourne, Perth Metro, Melville Water, Rottnest Is, Jandakot, etc | F5: /AED_Cockburn_db/CSIEM/Data/data-swamp/BOM/IDY | G5: BOM request | J5: data warehouse
A6: BOM-IDO | B6: BOM | C6: air temperature, barometric pressure, wind | D6: 1 | E6: Hillarys | F6: dataswamp_tmp UPDATE | G6: Web | H6: http://www.bom.gov.au/oceanography/projects/abslmp/data/index.shtml | J6: get latlong from this link pdf
A7: WWMSP-5.1-MET | B7: WAMSI | C7: Weather vars | D7: 1 | E7: Cockburn Cement | F7: \AED_Cockburn_db\CSIEM\Data\data-swamp\WAMSI\WWMSP5.1 - Hydrodynamics\WWMSP5.1\MET | G7: Sharepoint | J7: woodman
A8: DPIRD-AWS | B8: DPIRD | C8: Weather vars | D8: 5 | E8: WN, FL, BG, SP , WT | G8: Web or AED-Harvest (TBC) | H8: https://weather.agric.wa.gov.au
A9: UWA-AED | B9: UWA | C9: Weather vars | D9: 1 | E9: Matilda | G9: AED-Harvest | J9: café
B12: VIRTUAL WEATHER
A14: WWMSP-1.1-WRF | B14: WWMSP-1.1 | C14: Weather vars | D14: TBC | E14: Garden Island, Swanbourne, Perth Metro, Melville Water, Rottnest Is, Jandakot, etc | F14: TBC | G14: exported from WRF NC
A15: BOM-BARRA | B15: BOM | C15: Weather vars | D15: TBC | E15: Garden Island, Swanbourne, Perth Metro, Melville Water, Rottnest Is, Jandakot, etc | F15: TBC | G15: exported from BARRA-PH NC

Sheet HYDRODYNAMICS
A3: HYDRODYNAMICS | B3: Agency | C3: Variable | D3: #Sites | E3: Site Names | F3: Data Location | G3: Data Origin | H3: References / Further Information | I3: Master catalogue row# | J3: NOTES
A4: A | B4: Tides (water level stations)
A5: DOT-TIDE | B5: DOT (active) | C5: Water level | D5: 4 | E5: Barrack Street 02 (PTBAR02), Fremantle Fishing Boat Harbour (FFFBH01), Peel (PLPEE01), Mandurah Ocean Marina (MHMAN02) | F5: AED Dropbox\AED_Cockburn_db\CSIEM\Data\data-swamp\DOT\TIDE\TIDE2 | I5: 10
A6: DOT-TIDE | B6: DOT (historic) | C6: Water level | D6: 2 | E6: Mangles Bay (RKMGL01), Hillarys (HLHIL01), | F6: AED Dropbox\AED_Cockburn_db\CSIEM\Data\data-swamp\DOT\TIDE\TIDE2 | I6: 10
A7: FPA-TIDE | B7: FPA | C7: Water level | D7: 3 | E7: Stirling, Parmelia, North Mole | F7: 2011-2021 on Sharepoint, .mat file 2011-2016 (no northmole) on /csiem-marvl/scripting/thirdparty/bmt/calibration_hd/data/matfiles/CSound_Calibration | H7: BMT (2023): Page 46 | I7: 50 and 87 | J7: 2011-2021 on Sharepoint, .mat file 2011-2016 on CSIEM-Marvl from BMT (no northmole)
A8: BOM-IDO | B8: BOM | C8: Sea level, temp, air temp, barometric pressure, wind direction, wind gust, wind speed | D8: 1 | E8: Hillarys (IDO71012) | F8: \AED Dropbox\AED_Cockburn_db\CSIEM\Data\data-swamp\BOM\BOM\IDO | G8: Web | H8: http://www.bom.gov.au/oceanography/projects/abslmp/data/index.shtml | I8: 3
A10: B | B10: Wave buoys
A11: DOT-WAVE | B11: DOT (active) | C11: Sea component (Hs, Tp, Tm/T1, Dir); Swell component (Hs, Tp, Tm/T1, Dir); Total (Hs, Tp, Tm/T1) | D11: 3 | E11: Cottesloe (Deep Channel DCH38), Rottnest Island 02 (RDW47), Mandurah (MAN54), | F11: AED Dropbox\AED_Cockburn_db\CSIEM\Data\data-swamp\DOT\Waverider Buoys\WAVE2 | I11: 94
A12: DOT-WAVE | B12: DOT (historic) | C12: Sea/Swell/Total (Hs, Tp, Tz, Tm); Wave by Wave (Hs, Ts, Hmax, Thmax) | D12: 3 | E12: Cockburn (Owen Anchorage? OAM53), Dawesville 03 (DAW24), Rottnest Island 01 (ROT33) | F12: AED Dropbox\AED_Cockburn_db\CSIEM\Data\data-swamp\DOT\Waverider Buoys\WAVE2 | I12: 94 | J12: Sites Kwinana and Fremantle data unavailable for download on DOT website
A13: DOT-NWA | B13: DOT (via AODN) | C13: As above, standardised for National Wave Archive | D13: 11 | F13: /AED_Cockburn_db/CSIEM/Data/data-swamp/IMOS/2023/_AODN_NON_IMOS/National Wave Archive (DOT&UWA) | G13: AODN
A14: BMT-SWAN | B14: BMT (modelled) | C14: Hs (m), Peak Wave Period (s), Mean Wave Period (s), Peak Wave Direction (oN), Mean Wave Direction (oN) | D14: 3 | E14: North Berth , Mid Berth , South Berth | F14: CSIEM/Data/data-swamp/BMT/BMT Swan Wave Model | G14: BMT (2022) Breakwater Needs Assessment | H14: BMT (2022) : Page12
A15: UWA-WAVE | B15: UWA | C15: Hsig, Tp, Tm, Dp, DpSpr, Dm, DmSpr, SST, Bottom temp, Windspeed, Wind direction, CurrentMag, CurrentDirection | D15: 1 | E15: Hillarys | F15: C:\Users\00101765\AED Dropbox\AED_Cockburn_db\CSIEM\Data\data-swamp\UWA\WAWAVES | G15: Web | I15: 99 | J15: data has mismatch column names and values
A16: FPA-WAVE | B16: FPA | F16: /Volumes/SSD2/AED Dropbox/AED_Cockburn_db (DEP64896's conflicted copy 2023-08-03)/CSIEM/Data/data-swamp/FPA/Waves/FPA_PRESSURE
A17: WWMPSP5.2-WWM | B17: WWMPS (modelled) | C17: HS,DM,TPP | D17: 20 (REG) and 11 (CS) | E17: CS 'DAW24' 'DCH38' 'Hillarys' 'JPPLS01' 'JPPLS02' 'KWA01' 'OAM53' 'ORF01' 'PTB01' 'RDW47' 'ROT33' 'REG 'ALK01' 'ALK02' 'DAW24' 'DCH38' 'Hillarys' 'JPPLS01' 'JPPLS02' 'KWA01' 'MAN01' 'MAN02' 'MAN54' 'OAM53' 'ORF01' 'PTB01' 'RDW47' 'ROT33' 'TRK01' 'TRK02' 'TRK03' 'TRK04' | F17: /GIS_DATA/csiem-data-hub/data-lake/WAMSI/wwmsp5.2_waves/
A18: C | B18: AWAC (multi-sensor installations)
A19: DOT-AWAC | B19: DOT | C19: Current (Velocity, direction, depth at multiple depths), Temp; Status (pressure, heading, pitch, roll); Tide (water level); Wave (Swell/Sea/Total Hs, Tp, Tm, Tp_Dirn, Wave by wave Hmax, T_Hmax) | D19: 11 | E19: Alkimos 1 & 2, Ocean Reef, Two Rocks 1-4, Port Beach, Kwinana, Mandruah 1 & 2 | F19: \AED Dropbox\AED_Cockburn_db\CSIEM\Data\data-swamp\DOT\AWAC_V2 | I19: 95
A20: WWMSP-5.1-AWAC | B20: WWMSP 5.1 | C20: temp, DO, pressure, depth, conductivity, salinity, speed of sound, density anomaly, UCUR (eastward velocity), VCUR (northward velocity), heading, pitch, roll, PAR, Acceleration x, Acceleration y, Acceleration z | D20: 7 | E20: CS1-CS3 (4/2021); CS1-CS6 (11/2021) | F20: AED Dropbox\AED_Cockburn_db\CSIEM\Data\data-swamp\WWMSP\_WAMSI\WWMSP5.1 | I20: 96
A21: ? | B21: FPA | C21: temp, salinity, velocity, H, VMAG | D21: 3 | E21: Northern Basin, Spoil Grounds, Western Power | F21: csiem-marvl/scripting/thirdparty/bmt/calibration_hd/data/matfiles/CSound_Calibration/CSound_000_A7_20130101_20130601_ts.mat | H21: refer to report: BMT desalination plant discharge modelling | I21: 90 | J21: bmt compliled .mat file (2013) but not in report; also, refer to report: BMT desalination plant discharge modelling
A22: JPPL-AWAC | B22: JPPL | C22: velocity (multiple layers) | D22: 2 | E22: S01, S02 | F22: \AED Dropbox\AED_Cockburn_db\3_data\Data\JPPL\JPPL_AWAC; (12/2012 - 12/2013) | H22: BMT (2022) : Page A18 ; BMT (2023): Page 39-42 | I22: 85
A23: COC-AWAC | B23: COC (City of Cockburn) | C23: velocity (multiple layers) | D23: 2 | E23: Catherine 1 & 2 | F23: mentioned in BMT (2022) but no data | I23: 97
A24: CCL-AWAC | B24: CCL (Cockburn Cement Limited) | C24: velocity (multiple layers) | D24: 2 | E24: AWAC 1 & 2 | F24: mentioned in BMT report Breakwater needs wave modelling study but no data | I24: 98
A25: WCWA-PSDP-AWAC | B25: WCWA | C25: AWAC, oxygen, conductivity, temperature | D25: 4 | E25: A, B, C, D | F25: AED_Cockburn_db/CSIEM/Data/data-swamp/WC/BMT2018 | G25: BMT (2018) CS Metocean Data Summary | H25: BMT (2018)
A26: IMOS-ANMN | B26: IMOS | C26: Current velocity (TBC) | D26: 1 | E26: NRSROT | F26: AED_Cockburn_db/CSIEM/Data/data-swamp/IMOS/2023/ANMN/Current velocity time-series
B33: References
B34: BMT (2023) Development of a water quality response model for Cockburn Sound
B35: BMT (2022) Wave modelling study Breakwater Needs Assessment

Sheet WQ-PHYSCHM
A2: WQ-PHYSCHM | B2: Agency | C2: Variable | D2: #Sites | E2: Site Names | F2: Data Location | G2: Data Origin | H2: References / Further Information | I2: Master catalogue row# | J2: NOTES
A3: A | B3: Fixed-depth sensor
A4: DWER-CSMOORING | B4: DWER mooring | C4: bottom (0.5m from seabed): water temp, PAR, cond, turbidity, sal, DO, pH, DO%, depth, tilt, wavelength x 9 | D4: 4 | E4: 6147032.eastseagrass, 6147036.negardenisland, 6147037.westport, 6147033.manglesbay (with additional PAR and air temp on top of buoy) | F4: \AED Dropbox\AED_Cockburn_db\CSIEM\Data\data-swamp\DWER\Moorings\OneDrive_2023-06-20\Cockburn Sound Mooring data\Cockburn Sound Buoy Data | G4: Sharepoint | I4: 16
A5: DPIRD-CRP | B5: DPIRD | C5: 1m below surface: temp | D5: 3 | E5: Blue Lagoon Mussels Barge (MBS), South Jervois Bay Port Marker (JBM), NAJ (full name and location unknown) | F5: \AED Dropbox\AED_Cockburn_db\CSIEM\Data\data-swamp\DPIRD\Crab Research Program\Temperature | G5: Sharepoint | H5: Crab Research Program | I5: 43 | J5: Maybe NAJ is KGT Kwinana Grain Terminal
A6: BOM-IDO | B6: BOM (active) | C6: temp, air temp, barometric pressure, sea level,wind direction, wind gust, wind speed | D6: 1 | E6: Hillarys | F6: \AED Dropbox\AED_Cockburn_db\CSIEM\Data\data-swamp\BOM\BOM\IDO | G6: Web | I6: 3
A7: UWA-OI | B7: UWA (historic) | C7: SST, Bottom temp, Hsig, Tp, Tm, Dp, DpSpr, Dm, DmSpr, Windspeed, Wind direction, CurrentMag, CurrentDirection | D7: 1 | E7: Hillarys | F7: \AED Dropbox\AED_Cockburn_db\CSIEM\Data\data-swamp\UWA\WAWAVES | G7: Web | I7: 99 | J7: data has mismatch column names and values
A8: DOT-AWAC | B8: DOT (AWAC historic) | C8: Temp; Current (Velocity, direction, depth at multiple depths); Status (pressure, heading, pitch, roll); Tide (water level); Wave (Swell/Sea/Total Hs, Tp, Tm, Tp_Dirn, Wave by wave Hmax, T_Hmax) | D8: 11 | E8: Alkimos 1 & 2, Ocean Reef, Two Rocks 1-4, Port Beach, Kwinana, Mandruah 1 & 2 | F8: \AED Dropbox\AED_Cockburn_db\CSIEM\Data\data-swamp\DOT\AWAC_V2 | G8: Sharepoint | I8: 95
A9: DOT-NWA | B9: DOT (via AODN) | C9: As above, standardised for National Wave Archive | D9: 6 | E9: Cottesloe, Mandurah, Rottnest,Cockburn, Perth-canyon, Hillarys | F9: /AED_Cockburn_db/CSIEM/Data/data-swamp/IMOS/2023/_AODN_NON_IMOS/National Wave Archive (DOT&UWA) | G9: AODN
A10: IMOS-ANMN | B10: IMOS | C10: temp, salinity, DO, turbidity, CPHL, CNDC, DESC, DENS | D10: 1 | E10: NRSROT | F10: \AED Dropbox\AED_Cockburn_db\CSIEM\Data\data-swamp\IMOS\2023\ANMN\WQM and CTD | G10: AODN | I10: 29
A11: IMOS-ANMN | B11: IMOS | C11: temp, salinity | D11: 2 | E11: WACA20, NRSROT | F11: \AED Dropbox\AED_Cockburn_db\CSIEM\Data\data-swamp\IMOS\2023\ANMN\T and S time-series | G11: AODN | I11: 107
A12: WCWA-PSDP-BMT282 | B12: WC PSDP | C12: temp, EC, DO, pH | D12: 4 | E12: DO1A, DO2, DO4, DO7 | F12: \AED Dropbox\AED_Cockburn_db\CSIEM\Data\data-swamp\WCWA\Working\Working\2008\2008\BMT282 PSDP WQ Monitoring\Dissolved Oxygen Loggers | G12: Sharepoint | H12: Oceanica (2005) | I12: 64
A13: UWA-AED | B13: UWA | C13: T,EC,Chla etc | D13: 2 | E13: Kwilena, Matilda | F13: ? | G13: AED-Harvest
A14: UWA-OIGK | B14: UWA | C14: PAR | D14: 3 | E14: North, West (incorrect Northing given), East | F14: /AED_Cockburn_db/CSIEM/Data/data-swamp/UWA/OI-GK/Light Data Jun 97 to May 98 | G14: Sharepoint
A15: AIMS-SWT | B15: AIMS | C15: temp | D15: 5 | E15: Burns Rock, Centaur Reef, Bird Island, Penguin Is East, Becher Pt SZ | F15: /AED_Cockburn_db/CSIEM/Data/data-swamp/AIMS | G15: AODN
A16: WWMSP-2.2 | B16: WWMSP-2.2 | C16: PAR | D16: 1 | E16: Kwinana Shelf Cockburn Sound | F16: AED_Cockburn_db\CSIEM\Data\data-swamp\WAMSI\WWMSP2.2 - Seagrass Monitoring\2.2\Summary light data_Nov2022toJuly2023_Kwinana Cockburn Sound
A18: B | B18: Multi-depth sensor
A19: DWER-CSMOORING | B19: DWER mooring | C19: water temp, turb, sal, DO, pH, depth, tilt, wavelength x 9 | D19: 4 | E19: 6147030.northcs4, 6147031.southcs13, 6147034.south2cs11, 6147035.csdesal | F19: \AED Dropbox\AED_Cockburn_db\CSIEM\Data\data-swamp\DWER\Moorings\OneDrive_2023-06-20\Cockburn Sound Mooring data\Cockburn Sound Buoy Data | G19: Sharepoint | I19: 16
A20: WWMSP-5.1-WQ | B20: WWMSP 5.1 | C20: temp, DO, pressure, depth, conductivity, salinity, speed of sound, density anomaly, UCUR (eastward velocity), VCUR (northward velocity), heading, pitch, roll, PAR, Acceleration x, Acceleration y, Acceleration z | D20: 7 | E20: CS1-CS3 (4/2021); CS1-CS6 (11/2021) | F20: AED Dropbox\AED_Cockburn_db\CSIEM\Data\data-swamp\WWMSP\_WAMSI\WWMSP5.1 | G20: Sharepoint | I20: 96
A21: WCWA-PSDP-BMT349 | B21: WCWA | C21: seabed/mid water/surface: temp, salinity; seabed: DO | D21: 4 | E21: Site A (PSDP1 outlet), B (Central CS), C (Southern CS), D (Northern CS) | F21: AED_Cockburn_db\CSIEM\Data\data-swamp\WCWA\BMT349\BMT 349 Cockburn Sound Metocean Summary Report\Water Quality | G21: Sharepoint | H21: BMT (2018) | I21: 79
A22: WCWA-MMMP | B22: WC | C22: surface/middle/bottom: temp, salinity, velocity | D22: 3 | E22: Northern, Central and Southern Buoys | F22: csiem-marvl/scripting/thirdparty/bmt/calibration_hd/data/matfiles/CSound_Calibration/.. but no MMMP | G22: Sharepoint | H22: BMT (2023) p48, 54 | I22: 88 | J22: may be from profile data; MMMP may be the same as PSDP???
A23: WCWA-PSDP-? | B23: WC | C23: surface/bottom: DO | D23: 3 | E23: Northern, Central and Southern Buoys | F23: unavailable, mentioned in BMT (2023) | H23: BMT (2023) p114 | I23: 92 | J23: may be from profile data
A24: WCWA-PSDP-? | B24: WC | C24: surface/bottom: temp, salinity, velocity, H, DO | D24: 21 | E24: PSDP (21 sites grouped into inner, middle radii, outer) | F24: unavailable, mentioned in BMT (2023) | H24: BMT (2023) p49-51, 55-57, 115 | I24: 89 | J24: may be from profile data
B25: FPA (historic) | C25: temp, salinity, velocity, H, VMAG | D25: 3 | E25: Northern Basin, Spoil Grounds, Western Power | F25: csiem-marvl/scripting/thirdparty/bmt/calibration_hd/data/matfiles/CSound_Calibration/CSound_000_A7_20130101_20130601_ts.mat | H25: refer to report: BMT desalination plant discharge modelling | I25: 90
A27: C | B27: Profiles
A28: CSMC-CTD | B28: CSMC | C28: temp, salinity, conductivity, density, DO, pH, turbidity, Fluorescence | F28: /AED_Cockburn_db/CSIEM/Data/data-swamp/CSMC/Transmittal 1 - WQ/Files/KIC20-1_All Phys Data.xlsx
A29: IMOS-ANMN-CTD | B29: IMOS | C29: temp, salinity, DO, turbidity, CPHL, CNDC, DESC, DENS | D29: 1 | E29: NRSROT | F29: \AED Dropbox\AED_Cockburn_db\CSIEM\Data\data-swamp\IMOS\2023\ANMN\CTD profiles | G29: AODN | I29: 29
A30: UWA-CWR-CTD | B30: UWA | C30: temp, salinity, density | D30: 259 | E30: Multiple sites within each region: Cockburn, Mandurah, Garden Island, South Perth, North Perth | F30: \AED Dropbox\AED_Cockburn_db\CSIEM\Data\data-swamp\UWA\CWRCTD\CTD | G30: Sharepoint | I30: 32
A31: UWA-CWR-PCM | B31: UWA | C31: TBC | G31: ARMS
A32: WWMSP-3.1-CTD | B32: WWMSP 3.1 | C32: temp, salinity, conductivity, density, DO, pH, turbidity, Fluorescence, TSS | D32: 18 | E32: AJ, CSR14, INLET, JB16A, LP, MR, OA-1-DEP, OA1, OA2S, OA3, OA4, OA9S, PB, S4S10, SC, SC2, SF11, 1310 | F32: \AED Dropbox\AED_Cockburn_db\CSIEM\Data\data-swamp\WAMSI\WWMSP3.1 - Water & Sediment Quality\WWMSP3.1 | G32: Sharepoint | I32: 39
A33: WCWA-MMMP | B33: WC | C33: temp, salinity, DO | D33: 22 | E33: Central buoy, MMMP (21 sites) | F33: unavailable, mentioned in BMT (2023) | H33: BMT (2023) p52-53, 58-59, 118-119 | I33: 91 | J33: MMMP may be the same as PSDP???
A34: WCWA-PSDP-BMT282 | B34: WC PSDP | C34: temp, salinity, DO, DO%, pH, turbidity, light attenuation | D34: 14 | E34: WC1:8, WCT1:6 | F34: \AED Dropbox\AED_Cockburn_db\CSIEM\Data\data-swamp\WCWA\Working.zip\Working\2008\2008\BMT282 PSDP WQ Monitoring\Physical Profiles | G34: Sharepoint | H34: Oceanica (2005) | I34: 64
A35: WCWA-PSDP-BMT282 | B35: WC PSDP | C35: temp, EC, DO, pH | D35: 4 | E35: DO1A, DO2, DO4, DO7 | F35: AED_Cockburn_db/data_swamp/WCWA/PSDP/BMT282 (2008 WQ Monitoring)/BMT282 PSDP WQ Monitoring/Dissolved Oxygen Loggers | G35: Sharepoint | H35: Oceanica (2005) | I35: 64
A36: ? | B36: WC PLOOM | C36: temp, salinity, EC, DO, DO%, density | D36: 12 | E36: N1:3, N6, S1:3, S5, SB1:3, SB5 | F36: \AED Dropbox\AED_Cockburn_db\CSIEM\Data\data-swamp\WCWA\Working\Working\2008\2008\BMT271 WaterCorp PLOOM\SeasonalWQ\Physical\PLOOM\PLOOM4.3 | G36: Sharepoint | I36: 108
A37: ? | B37: WC PSDP Fauna | C37: temp, salinity, DO, DO%, pH, turbidity | D37: 77 | E37: C1:77 | F37: sharepoint | G37: Sharepoint | H37: Oceanica (2007) | I37: 71 | J37: this file is curerntly not on dropbox due to errors unzipping
A38: CSIRO-O&ACTD | B38: CSIRO | C38: temp, salinity, DO, PAR, conductivity, fluorescence, nitrate, optode | D38: 192? | E38: station 1:261, 12009 | F38: \AED Dropbox\AED_Cockburn_db\CSIEM\Data\data-swamp\CSIRO\O&ACTD\MNF_ctd_164415 and ...\CSIRO\O&AXBT\MNF_xbt_165601 | G38: AODN | H38: collated data from various projects | I38: 109 | J38: location for each site changes from year to year
A39: DWER-SWANEST | B39: DWER | C39: temp, salinity, DO, DO%, pH, turbidity (TBC) | G39: WIR
A40: DWER-CSMWQ | B40: DWER | C40: temp, salinity, DO, DO%, pH, turbidity (TBC) | G40: WIR
A41: FPA? | B41: FPA | C41: temp, salinity, DO, DO%, pH, turbidity (TBC) | G41: WIR?
A43: D | B43: Grab/Point
A44: CSMC-WQ | B44: CSMC | C44: suface/bottom: temp, salinity, conductivity,DO, DO sat, pH, turbidity, Flouro, density; TN, TP, AMM, NIT, ORTHO-P, Chla, Chlb, Chlc, light, TSS, POC | D44: 23 | E44: current: CS4, CS5, CS6A, CS7, CS8, 9, CS9A, CS10N, CS11, CS12, G1, G2, G3, WS4, WSSB, WSSB-L, NH3, SF, SF-L, CB, CB13, MB, MB-L; historical: NC, SC, CS10 (now CS10N), CS6 (now CS6A) | F44: \AED Dropbox\AED_Cockburn_db\CSIEM\Data\data-swamp\CSMC\CSMWQ-MAFRL | H44: BMT (2023) p80-112 (14 sites only) | I44: 8 | J44: was CSMC-MAFRL
...

Sheet WQ-NUTRIENT
A2: WQ-NUTRIENT | B2: Agency | C2: Variable | D2: #Sites | E2: Site Names | F2: Data Location | G2: Data Origin | H2: References / Further Information | I2: Master catalogue row# | J2: NOTES
B3: Water Quality Grab Samples
A5: DWER-SWANEST | B5: DWER | C5: ammonium, Chla, Chlc,DOC,FRP,Nitrate,DO sat, DO, pH,… | D5: 26 | E5: 616xxxx | F5: data warehouse
A6: DWER-CANEST | B6: DWER | C6: ammonium, Chla, Chlc,DOC,FRP,Nitrate,DO sat, DO, pH,… | D6: 17 | E6: 616xxxx | F6: data warehouse
A7: CSMC-WQ | B7: CSMC | C7: C, Chla, Chlb, Chlc, conductivity, TN, DON, TON, TKN,NH3-N/NH4-N, TP, FRP, pH, DO, DOsat, Phaeophytin a , salnity, secchi depth, TSS, Turbidity, temp, alkalinity… | D7: 23 | E7: current: CS4, CS5, CS6A, CS7, CS8, 9, CS9A, CS10N, CS11, CS12, G1, G2, G3, WS4, WSSB, WSSB-L, NH3, SF, SF-L, CB, CB13, MB, MB-L; historical: NC, SC, CS10 (now CS10N), CS6 (now CS6A) | F7: data warehouse
A8: DWER-CSMWQ | B8: DWER | C8: C, Chla, Chlb, Chlc, conductivity, TN, DON, TON, TKN,NH3-N/NH4-N, TP, FRP, pH, DO, DOsat, Phaeophytin a , salnity, secchi depth, TSS, Turbidity, temp, alkalinity, ... | D8: 19 | E8: 616xxxx | F8: AED_Cockburn_db\CSIEM\Data\data-swamp\DWER\CSMWQ
A9: IMOS-BGC | B9: IMOS | C9: Salinity, DO, alkalinity, Secchi depth, DIC, amm, Nitrate, Nitrite, Phosphate, TSS, silicate, Prochlorococcus… | D9: 1 | E9: NRSROT | F9: \AED Dropbox\AED_Cockburn_db\CSIEM\Data\data-swamp\IMOS\2023\REFSTN\BGC
A10: FPA-MQMP | B10: FPA | C10: ammonia, TN, TP, NO3+NO2, OrthoP, Chla-c, DOC, Phaeophytina a, metals and contaminants… | D10: 29 | E10: BR1, DW1:3, FP1… | F10: AED_Cockburn_db\CSIEM\Data\data-swamp\FPA\MQMP
A11: WCWA-PSDP-BMT282 | B11: WC PSDP | C11: ammonia, OrthoP, Phaeophytina a, metals | D11: 8 | E11: WC1:8 | F11: AED_Cockburn_db\CSIEM\Data\data-swamp\WCWA\Working\Working\2008\2008\BMT282 PSDP WQ Monitoring\Nutrients\ Prim Prod and Solids\
A12: WC-PLOOM-BMT271 | B12: WC PLOOM | C12: ammonia, OrthoP, TN, TP, Chl, Phaeophytina a, metals | D12: 12 | E12: N1:3, N6, S1:3, S5, SB1:3, SB5 | F12: \AED_Cockburn_db\CSIEM\Data\data-swamp\WCWA\Working\Working\2022\BMT271 WaterCorp PLOOM_all\SeasonalWQ\Nutrients\PLOOM\
A13: WC-PLOOM-TWW | B13: WC PLOOM | C13: TN, TP, DOC, Chl, Nox, NH3, TSS, pH, BOD, contaminants | D13: 3 | E13: Beenyup WWTP, Subiaco WWTP, Sepia Depression WWTP | F13: AED_Cockburn_db\CSIEM\Data\data-swamp\WCWA\Working\Working\2022\BMT271 WaterCorp PLOOM_all\ComprehensiveTWW\Physico-chemical\PLOOM\PLOOM7.7 | J13: site locations unknown
A14: WC SDOOL | B14: WC SDOOL | C14: ? | D14: ?
B16: Other

Sheet WQ-SEDIMENT
A2: WQ-SEDIMENT | B2: Agency | C2: Variable | D2: #Sites | E2: Site Names | F2: Data Location | G2: Data Origin | H2: References / Further Information | I2: Master catalogue row# | J2: NOTES
A3: A | B3: Sediment Size/Type (PSD)
A5: GA-SS | B5: GA | D5: 2 | E5: SS082005/01GR02,SS082005/01GR03 | F5: AED_Cockburn_db\CSIEM\Data\data-swamp\GA\MARS\ | G5: MARS
A6: GA-ROT | B6: GA | D6: 18 | E6: C169001, C170003,…etc | F6: AED_Cockburn_db\CSIEM\Data\data-swamp\GA\MARS\ | G6: MARS
A8: B | B8: Sediment Grab (Bulk surface chemistry)
A10: GA-CS251 | B10: GA | D10: 63 | E10: 251/CSG002,…251/CSG074 | F10: AED_Cockburn_db\CSIEM\Data\data-swamp\GA\MARS\ | G10: MARS | H10: Skene et al. 2005 | J10: particle size
A11: WCWA-PSDP-BMT320 | B11: WCWA | D11: 46 | E11: C6:C85 | F11: AED_Cockburn_db\CSIEM\Data\data-swamp\WCWA\Working\Working\2009\2009\BMT320 Perth Metropolitan Desalination Plant - Cockburn Sound Benthic Macrofauna Community and Sediment Habitat\Sediment | G11: Sharepoint | J11: sed site names may be the same as fauna sites but coordinates are different
A12: WCWA-PSDP-BMT337 | B12: WCWA | D12: 46 | E12: C6:C86 | F12: AED_Cockburn_db\CSIEM\Data\data-swamp\WCWA\Working\Working\2013\2013\BMT337 Perth Metropolitan Desalination Plant – Cockburn Sound Benthic Macrofauna Community and Sediment Habitat – Repeat Survey 2013\Sediments PSD | G12: Sharepoint
A13: WWMSP3.1-SEDPSD | B13: WWMSP3.1 | D13: 22 | E13: OA1, AJ, 3000, ..etc | F13: sharepoint | G13: Sharepoint | J13: no data?
A14: WWMSP3.1-SGREST | B14: WWMSP3.1 | D14: 10 | E14: CS_R14, S4S1-2021 ..etc | F14: sharepoint | G14: Sharepoint | J14: no data?
A15: FPA-MQMP | B15: FPA | D15: 30 | E15: FP1, FP3, KBJ1, … | F15: AED_Cockburn_db\CSIEM\Data\data-swamp\FPA\MQMP\MQMP2002-2021_WQ_20210728.xlsx | G15: Sharepoint
A16: GA-258 | B16: GA | D16: 9 | E16: SR1:SR6, SR29:31 | F16: AED_Cockburn_db\CSIEM\Data\data-swamp\GA\MARS\ | G16: MARS
A17: GA-301 | B17: GA | D17: 4 | E17: SR1,SR5:SR6, SR32:34 | F17: AED_Cockburn_db\CSIEM\Data\data-swamp\GA\MARS\ | G17: MARS
A18: WCWA-SDOOL-BMT345 | B18: WCWA | D18: 7 | E18: M1:3, S1:3, Ref1 | F18: AED_Cockburn_db\CSIEM\Data\data-swamp\WCWA\Working\Working\2015\2015\BMT345 Sepia Depression Ocean Outlet Landline – Metals and Pesticides Survey 2015\Sediment | G18: Sharepoint
A19: GA-FR | B19: GA | D19: 1 | E19: FR01 | F19: AED_Cockburn_db\CSIEM\Data\data-swamp\GA\MARS\ | G19: MARS
A20: GA-334 | B20: GA | D20: 32 | E20: GA334/01GR02,GA334/03GR06,…etc | F20: AED_Cockburn_db\CSIEM\Data\data-swamp\GA\MARS\ | G20: MARS
A21: WP-SED | B21: WP | D21: 40 | E21: KS1:30, C1:10 | F21: https://uniwa.sharepoint.com/teams/EXT-WAMSIWestportReportsandData/Shared%20Documents/Forms/AllItems.aspx?ga=1&id=%2Fteams%2FEXT%2DWAMSIWestportReportsandData%2FShared%20Documents%2FHistorical%5FData%5FCockburn%5FSound%2FWAMSI%5FWestport%5Fproject%5Fuse%5FONLY%2FWestport%2FRPS%20Sediment%20Sampling%20Study%5FResults%2Ezip&viewid=c4258036%2D8243%2D46aa%2Db02e%2D6bde95ff5f4d&parent=%2Fteams%2FEXT%2DWAMSIWestportReportsandData%2FShared%20Documents%2FHistorical%5FData%5FCockburn%5FSound%2FWAMSI%5FWestport%5Fproject%5Fuse%5FONLY%2FWestport | G21: Sharepoint
A22: WWMSP3.1-SEDDEPO | B22: WWMSP3.1 | D22: 5 | E22: CSR14 CSSF JB16A OA1 S4S10 | F22: /GIS_DATA/csiem-data-hub/data-lake/WAMSI/WWMSP3.1 - Sediment Deposition Logger/Sediment Deposition Logger Data
A24: C | B24: Sediment Chemistry (porewater etc)
A29: D | B29: Sediment Fluxes
A31: WWMSP-3.1-DL | B31: WWMSP3.1 | D31: 6 | E31: S4S2-DL,OA1-DL,JB16A-L,S4S10-L.. | F31: sharepoint | G31: Sharepoint | J31: no data?
A32: GA-258 | B32: GA | D32: 9 | E32: SR1:SR6, SR29:31 | F32: AED_Cockburn_db\CSIEM\Data\data-swamp\GA\MARS\ | G32: MARS
A33: GA-301 | B33: GA | D33: 6 | E33: SR1,SR5:SR6, SR32:34 | F33: AED_Cockburn_db\CSIEM\Data\data-swamp\GA\MARS\ | G33: MARS
A34: WSACB-1.1 | B34: WSACB1.1 | D34: 31 | E34: JV007, MM1:4, AA,BB,City Beach, Jervoise Bank ..etc | F34: ? | H34: AED_Cockburn_db\2_literature\WAMSI_Final_Report_Node_1_Project 1_all chapters.pdf
A36: E | B36: Sediment Cores
A37: GA-CS251 | B37: GA | D37: 12 | E37: 251/CSV001, 251/CSV002, ...251/CSV013 | F37: AED_Cockburn_db\CSIEM\Data\data-swamp\GA\MARS\ | G37: MARS | H37: Skene et al. 2005
A38: GA-334 | B38: GA | D38: 8 | E38: GA334/01GC01,GA334/05GC05…etc | F38: AED_Cockburn_db\CSIEM\Data\data-swamp\GA\MARS\ | G38: MARS
A40: F | B40: Sedimentation Rate
A41: WP-SED | B41: WP | D41: 40 | E41: KS1:30, C1:10 | F41: https://uniwa.sharepoint.com/teams/EXT-WAMSIWestportReportsandData/Shared%20Documents/Forms/AllItems.aspx?ga=1&id=%2Fteams%2FEXT%2DWAMSIWestportReportsandData%2FShared%20Documents%2FHistorical%5FData%5FCockburn%5FSound%2FWAMSI%5FWestport%5Fproject%5Fuse%5FONLY%2FWestport%2FRPS%20Sediment%20Sampling%20Study%5FResults%2Ezip&viewid=c4258036%2D8243%2D46aa%2Db02e%2D6bde95ff5f4d&parent=%2Fteams%2FEXT%2DWAMSIWestportReportsandData%2FShared%20Documents%2FHistorical%5FData%5FCockburn%5FSound%2FWAMSI%5FWestport%5Fproject%5Fuse%5FONLY%2FWestport | G41: Sharepoint

Sheet WQ-LIGHT
A1: WQ-LIGHT | B1: Agency | C1: Variable | D1: #Sites | E1: Site Names | F1: Data Location | G1: Data Origin | H1: References / Further Information | I1: Master catalogue row# | J1: NOTES
A2: A | B2: Turbidity and extinction
A3: CSMC-WQ | B3: CSMC | C3: C, Chla, Chlb, Chlc, conductivity, TN, DON, TON, TKN,NH3-N/NH4-N, TP, FRP, pH, DO, DOsat, Phaeophytin a , salnity, secchi depth, TSS, Turbidity, temp, alkalinity… | D3: 23 | E3: current: CS4, CS5, CS6A, CS7, CS8, 9, CS9A, CS10N, CS11, CS12, G1, G2, G3, WS4, WSSB, WSSB-L, NH3, SF, SF-L, CB, CB13, MB, MB-L; historical: NC, SC, CS10 (now CS10N), CS6 (now CS6A) | F3: data warehouse
A4: DWER-CSMWQ | B4: DWER | C4: C, Chla, Chlb, Chlc, conductivity, TN, DON, TON, TKN,NH3-N/NH4-N, TP, FRP, pH, DO, DOsat, Phaeophytin a , salnity, secchi depth, TSS, Turbidity, temp, alkalinity, ... | D4: 19 | E4: 616xxxx | F4: AED_Cockburn_db\CSIEM\Data\data-swamp\DWER\CSMWQ
A5: DWER-CSMOORING | B5: DWER mooring | C5: water temp, PAR, cond, turbidity, sal, DO, pH, DO%, depth, tilt, wavelength x 9 | D5: 9 | E5: 6147032.eastseagrass, 6147036.negardenisland, 6147037.westport, 6147033.manglesbay (with additional PAR and air temp on top of buoy), 6147030.northcs4 (decommissioned after May 2023), 6147031.southcs13, 6147034.south2cs11, 6147035.csdesal, cs86 (added after May 2023, site location unknown) | F5: \AED Dropbox\AED_Cockburn_db\CSIEM\Data\data-swamp\DWER\Moorings\OneDrive_2023-06-20\Cockburn Sound Mooring data\Cockburn Sound Buoy Data | G5: Sharepoint | I5: 16 | J5: no data for cs86
A9: B | B9: PAR
A10: WWMSP-5.1-AWAC | B10: WWMSP 5.1 | C10: temp, DO, pressure, depth, conductivity, salinity, speed of sound, density anomaly, UCUR (eastward velocity), VCUR (northward velocity), heading, pitch, roll, PAR, Acceleration x, Acceleration y, Acceleration z | D10: 3 | E10: CS4:CS6 | F10: AED Dropbox\AED_Cockburn_db\CSIEM\Data\data-swamp\WWMSP\_WAMSI\WWMSP5.1 | I10: 96
A11: UWA-OI-GK | B11: UWA | C11: PAR | D11: 3 | E11: North, West (incorrect Northing given), East | F11: /AED_Cockburn_db/CSIEM/Data/data-swamp/UWA/OI-GK/Light Data Jun 97 to May 98 | G11: Sharepoint | J11: Corrected west site northing provided by Gary via email (through Matt 6/10/2023)
A14: C | B14: Multi-spectral
A15: WWMSP-2.2 | B15: WWMSP-2.2 | C15: PAR (ambient and shading experiment) | D15: 1 | E15: Kwinana Shelf | F15: AED Dropbox\AED_Cockburn_db\CSIEM\Data\data-swamp\WAMSI\WWMSP2.2 - Seagrass Monitoring\Light Data\Light data Mastersheet_July2023-2.xlsx
A16: DWER-CSMOORING | B16: DWER mooring | C16: water temp, PAR, cond, turbidity, sal, DO, pH, DO%, depth, tilt, wavelength x 9 | D16: 9 | E16: 6147032.eastseagrass, 6147036.negardenisland, 6147037.westport, 6147033.manglesbay (with additional PAR and air temp on top of buoy), 6147030.northcs4 (decommissioned after May 2023), 6147031.southcs13, 6147034.south2cs11, 6147035.csdesal, cs86 (added after May 2023, site location unknown) | F16: \AED Dropbox\AED_Cockburn_db\CSIEM\Data\data-swamp\DWER\Moorings\OneDrive_2023-06-20\Cockburn Sound Mooring data\Cockburn Sound Buoy Data | G16: Sharepoint | I16: 16 | J16: no data for cs86
A19: D | B19: Above-water
A20: WWMSP-5.1-MET | B20: WAMSI | C20: PAR, weather vars | D20: 1 | E20: Cockburn Cement | F20: \AED_Cockburn_db\CSIEM\Data\data-swamp\WAMSI\WWMSP5.1 - Hydrodynamics\WWMSP5.1\MET | G20: Sharepoint | J20: woodman
B21: Mangles Bay AquaWatch | C21: TBC
A22: DWER-CSMOORING | B22: DWER mooring | C22: bottom (0.5m from seabed): water temp, PAR, cond, turbidity, sal, DO, pH, DO%, depth, tilt, wavelength x 9 | D22: 2 | E22: 6147033.manglesbay (with additional PAR and air temp on top of buoy), LandRefPAR (location estimated from satellite) | F22: \AED Dropbox\AED_Cockburn_db\CSIEM\Data\data-swamp\DWER\Moorings\OneDrive_2023-06-20\Cockburn Sound Mooring data\Cockburn Sound Buoy Data | G22: Sharepoint | I22: 16 | J22: 6147033 data can be unreliable due to station tilt; LandRefPAR data not available

Sheet ECO-PLANKTON
A2: ECO-PLANKTON | B2: Agency | C2: Variable | D2: #Sites | E2: Site Names | F2: Data Location | G2: Data Origin | H2: References / Further Information | I2: Master catalogue row# | J2: NOTES
A3: A | B3: Phytoplankton Cell Counts
A5: DWER-SWANEST-PHY | B5: DWER | D5: 11 | E5: 616XXXX | F5: https://github.com/AquaticEcoDynamics/SCERM_private/tree/master/matlab/BIO_Import
A6: DWER-CSMWQ-PHY | B6: DWER | D6: 25 | E6: CS10:13, CS4:9A, DESAL, MB,... etc. | F6: /AED_Cockburn_db/CSIEM/Data/data-swamp/DWER/Phytoplankton/KP-M-CSMWQ_ALL SPECIES DATA_WAMSI.xlsx
A7: WCWA-PLOOM-BMT271 | B7: WCWA | D7: 42 | E7: OR11, SB3, SD1.. etc. (site locations unknown) | F7: https://uniwa.sharepoint.com/teams/EXT-WAMSIWestportReportsandData/Shared%20Documents/Forms/AllItems.aspx?ga=1&id=%2Fteams%2FEXT%2DWAMSIWestportReportsandData%2FShared%20Documents%2FHistorical%5FData%5FCockburn%5FSound%2FWAMSI%5FWestport%5Fproject%5Fuse%5FONLY%2FWater%20Corporation%2FPLOOM%2FBMT271%20WaterCorp%20PLOOM%5Fall%2FSummerWQ%2FPhytoplankton%2FPLOOM%2FPLOOM%207%2E7&viewid=c4258036%2D8243%2D46aa%2Db02e%2D6bde95ff5f4d
A8: CSIRO-APD | B8: CSIRO | D8: 48 | E8: site names not provided, assigned as "Project ID_a","Project ID_b"…etc | F8: \AED_Cockburn_db\CSIEM\Data\data-swamp\CSIRO\Australian Phytoplankton Database | J8: some sites were surveyed repeatedly in different projects
A9: IMOS-REFSTN | B9: IMOS | D9: 1 | E9: ROT | F9: \AED_Cockburn_db\CSIEM\Data\data-swamp\IMOS\2023\REFSTN\PHY
A10: WCWA-PSDP-BMT282 | B10: WCWA | D10: 8 | E10: WC1:8 | F10: https://uniwa.sharepoint.com/teams/EXT-WAMSIWestportReportsandData/Shared%20Documents/Forms/AllItems.aspx?ga=1&id=%2Fteams%2FEXT%2DWAMSIWestportReportsandData%2FShared%20Documents%2FHistorical%5FData%5FCockburn%5FSound%2FWAMSI%5FWestport%5Fproject%5Fuse%5FONLY%2FWater%20Corporation%2FPDSP%2F2008%2FBMT282%20PSDP%20WQ%20Monitoring%2FPhytoplankton&viewid=c4258036%2D8243%2D46aa%2Db02e%2D6bde95ff5f4d
A11: IMOS-CPR | B11: IMOS | D11: 4 | E11: 350-67, 60-1, …etc (no site names, used sampleID instead | F11: AED_Cockburn_db\CSIEM\Data\data-swamp\IMOS\2023\CPR\Phyto
A12: WASQAP | B12: WASQAP | D12: 6? | E12: Southern Flats, Kwinana Beach | F12: no data | H12: AED_Cockburn_db\6_presentations\Fish Kills - Copy | J12: Western Australian Shellfish Quality Assurance Program
B13: Southern Metropolitan Coastal Waters Study | D13: 47 | F13: ? | H13: AED_Cockburn_db\6_presentations\Fish Kills - Copy
A14: UWA-AED | D14: ?
A17: B | B17: Zooplankton
A19: WWMSP-4.2-ZOO | B19: WWMSP | C19: Zooplankton abundance and biomass | D19: 15 | E19: CS6, CS91, CS27, OW43:45 … etc | F19: no data | H19: /AED Dropbox/AED_Cockburn_db/5_reporting/4.2/202212_Project_4.2.2_Progress_report_2_ Zooplankton.docx
A20: IMOS-REFSTN | B20: IMOS | D20: 1 | E20: ROT | F20: \AED_Cockburn_db\CSIEM\Data\data-swamp\IMOS\2023\REFSTN\ZOOP
A21: IMOS-CPR | B21: IMOS | D21: 3 | E21: 186-21,186-25, 60-1(no site names, used sampleID instead | F21: \AED_Cockburn_db\CSIEM\Data\data-swamp\IMOS\2023\CPR\Zoops
A26: C | B26: Productivity Measures

Sheet ECO-BENTHIC
A2: ECO-BENTHIC | B2: Agency | C2: Variable | D2: #Sites | E2: Site Names | F2: Data Location | G2: Data Origin | H2: References / Further Information | I2: Master catalogue row# | J2: NOTES
A3: A | B3: Seagrass & Macroalgae
A6: WWMSP-2.2-SG | B6: WWMSP | C6: P.sinuosa count, depth, habitat type, lat/long, transect #, year (no date); dominant algae type, density (categorical) | D6: 61 (includes sites outside of CS; only 24 for algae) | E6: Becher Point, Bird Island etc. | F6: \AED_Cockburn_db\CSIEM\Data\data-swamp\WAMSI\WWMSP2.2 - Seagrass Monitoring\Theme2.2_EditedData\Driver of Seagrass Condition_Regional for Hipsey_edited.xlsx & Cockburn Seagrass Algal Cover and Type for Hipsey_edited.xlsx
A7: CSMC-SG | B7: CSMC | C7: seagrass count (multiple species), epiphyte type/cover, seagrass height, lower depth limit, transect/quadrat#, depth, date; dominant/non-dominant epiphyte type, cover (% or categorical), epiphyte biomass; Depth transect sites: Leading edge/depth, lower depth limit distance/depth | D7: 58 (includes depth transect sites) | E7: Becher Point, Bird Island, Garden Island North_DEPTH etc. | F7: \AED_Cockburn_db\CSIEM\Data\data-swamp\WAMSI\WWMSP2.2 - Seagrass Monitoring\Theme2.2_EditedData\CSMC_Data_Historical_2003-2022_algae_edited.xlsx & Depth transect data summary_edited.xlsx | J7: has a lot more info than WWMSP-2.2-SG but not QAQC'd
A8: WCWA-PLOOM
A9: CSMC-SG-2015 | B9: CSMC | C9: P.sinuosa count, depth, biomass (above/below), productivity, epiphytes biomass, leaf/root sulfur %, rhizome heavy metals, sediment heavy metals, sed porosity,sed OM, seagrass P%, sed P% | D9: 12 | E9: GI2, GI3, WS2, WS3… | F9: AED Dropbox\AED_Cockburn_db\CSIEM\Data\data-swamp\WAMSI\WWMSP2.2 - Seagrass Monitoring\2015 seagrass sediment stressors data.xlsx | G9: https://figshare.com/s/3e705529e7c311830c33 | H9: Fraser & Kendrick 2017. Belowground stressors and long-term seagrass declines in a historically degraded seagrass ecosystem after improved water quality | J9: sampled in 2015 Mar - May
A10: ECU-2003 | B10: ECU | C10: P.sinuosa shoot count, biomass (above/below), epiphyte biomass, depth, leaf morphology, leaf growth, light | D10: 2 transects * 6 depths | E10: CS, WS | F10: AED Dropbox\AED_Cockburn_db\CSIEM\Data\data-swamp\WAMSI\WWMSP2.2 - Seagrass Monitoring\2003 seagrassVSdepth data.xlsx | G10: digitised from Fig.3 in Collier et al. 2007 (only shoot count, biomass and depth were digitised) | H10: Collier et al. 2007. Morphological, growth and meadow characteristics of the seagrass Posidonia sinuosa along a depth-related gradient of light availability | J10: sampled in 2002 Jun and 2003 Jan-Feb
A11: ECU-1993 | B11: ECU | C11: P.sinuosa shoot count, biomass (above), velocity | D11: 2 | E11: Inshore, offshore (Shoalwater bay) | F11: AED Dropbox\AED_Cockburn_db\CSIEM\Data\data-swamp\WAMSI\WWMSP2.2 - Seagrass Monitoring\1993 Keulen seagrass data.xlsx | G11: digitised from Fig.5.1 & 5.2 in Keulen 1998 (only shoot count and biomass were digitised) | H11: Keulen 1998. Water flow in seagrass ecosystems | J11: sampled on 7 occasions between 1991 Dec - 1993 Feb
A17: B | B17: Benthic Infauna
A19: WCWA-PLOOM
A20: WCWA-PSDP
A21: WWMSP-2.4
A26: C | B26: Productivity Measures
A28: WSACB-1.1 | B28: TBC

Sheet DISCHARGES
A1: Discharges

Sheet OLD->

Sheet CATALOGUE (old)
A1: row# | B1: Table | C1: CSIEM Category | D1: Ownership | E1: Group | F1: Agency / Organisation | G1: Agency ID | H1: Program | I1: Program Code | J1: Data Classification | K1: No of Sites | L1: Timing | M1: Date Last Updated | N1: Date Range | O1: Sites Mapped | P1: Import Status | Q1: Priority | R1: Science Review | S1: Notes | T1: Link / Reference | U1: Notes_SZ
A2: 2 | B2: Data | C2: Weather | D2: Public | E2: National Facilities | F2: Bureau of Meteorology | G2: BOM | H2: Weather | I2: IDY | J2: MET General | K2: 16 | L2: Ongoing | O2: Y | P2: Data Warehouse | Q2: High
A3: 3 | B3: Data | C3: Weather | D3: Public | E3: National Facilities | F3: Bureau of Meteorology | G3: BOM | H3: Australian Baseline Sea Level Monitoring Project | I3: IDO | J3: HYDRO Level | K3: 1 | L3: Ongoing | O3: N | P3: Action Required | Q3: Low | U3: Site: Hillarys. See 'waves' sheet
A4: 4 | B4: Data | C4: Validation-Hydro | D4: Public | E4: National Facilities | F4: Bureau of Meteorology | G4: BOM | H4: Australia Rainfall and River Conditions | I4: IDW | J4: HYDRO Flow | K4: 1 | L4: Ongoing | O4: N | P4: Action Required | Q4: Low
A5: 5 | B5: Data | C5: Groundwater | D5: Public | E5: National Facilities | F5: Bureau of Meteorology | G5: BOM | H5: Australian Groundwater Data | I5: NGIS | J5: GW Level | K5: # | L5: Ongoing | O5: N | P5: Action Required | Q5: Low
A6: 6 | B6: Data | C6: Validation-WQ | D6: Private | E6: Local Provider | F6: BP Refinery | G6: BPR | H6: BP Refinery Kwinana | I6: BPR-WQ | J6: WQ Grab | K6: 1 | L6: Ongoing | O6: N | P6: Action Required | Q6: Medium
A7: 7 | B7: Data | C7: Validation-WQ | D7: Private | E7: Local Provider | F7: CSBP Limited | G7: CSBP | H7: CSBP Limited | I7: CSBP-WQ | J7: WQ Grab | K7: 1 | L7: Ongoing | O7: N | P7: Action Required | Q7: Medium
A8: 8 | B8: Data | C8: Validation-WQ | D8: Private | E8: State Agencies | F8: Cockburn Sound Management Council | G8: CSMC | H8: Cockburn Sound Marine Water Quality Monitoring | I8: CSMWQ-MAFRL | J8: WQ Grab | K8: 23 | L8: Fixed | O8: N | P8: Data Warehouse | Q8: High | S8: Site info missing for some sites. Missing data not in warehouse
A9: 9 | B9: Data | C9: Knowledge | D9: Private | E9: State Agencies | F9: Department of Biodiversity, Conservation and Attractions | G9: DBCA | H9: Cockburn Sound Env Study (1970) | I9: DEC-CSES | L9: Fixed | O9: N | P9: Action Required | Q9: Medium
A10: 10 | B10: Data | C10: Validation-Hydro | D10: Public | E10: State Agencies | F10: Department of Transport | G10: DOT | H10: Coastal Data | I10: TIDE | J10: HYDRO Level | K10: 5 | L10: Ongoing | O10: Y | P10: Data Warehouse | Q10: High | U10: Sites: Barrack Street 02 (PTBAR02), Fremantle Fishing Boat Harbour (FFFBH01), Peel (PLPEE01, not in warehouse yet), Mangles Bay (RKMGL01), Hillarys (HLHIL01). See 'waves' sheet
A11: 11 | B11: Data | C11: Weather | D11: Public | E11: State Agencies | F11: Department of Primary Industries and Regional Development | G11: DPIRD | H11: Automatic Weather Stations | I11: AWS | J11: MET General | K11: # | L11: Ongoing | O11: N | P11: Action Required | Q11: Medium
A12: 12 | B12: Data | C12: Validation-WQ | D12: Public | E12: State Agencies | F12: Department of Water and Environmental Regulation | G12: DWER | H12: Swan Canning Estuary Monitoring | I12: SWANEST | J12: WQ Grab | K12: 26 | L12: Ongoing | O12: Y | P12: Data Warehouse | Q12: High
A13: 13 | B13: Data | C13: Validation-WQ | D13: Public | E13: State Agencies | F13: Department of Water and Environmental Regulation | G13: DWER | H13: Swan Catchment Sampling | I13: SWANCATCH | J13: WQ GRAB; HYDRO Flow | K13: 18 | L13: Ongoing | O13: Y | P13: Data Warehouse | Q13: High
A14: 14 | B14: Data | C14: Validation-WQ | D14: Public | E14: State Agencies | F14: Department of Water and Environmental Regulation | G14: DWER | H14: Canning River Estuary Sampling | I14: CANEST | J14: WQ Grab | K14: 17 | L14: Ongoing | O14: Y | P14: Data Warehouse | Q14: High
A15: 15 | B15: Data | C15: Validation-WQ | D15: Public | E15: State Agencies | F15: Department of Water and Environmental Regulation | G15: DWER | H15: Cockburn Sound Marine Water Quality Monitoring | I15: CSMWQ | J15: WQ Grab | K15: 19 | L15: Ongoing | O15: Y | P15: Data Warehouse | Q15: High
A16: 16 | B16: Data | C16: Validation-WQ | D16: Public | E16: State Agencies | F16: Department of Water and Environmental Regulation | G16: DWER | H16: Cockburn Sound Moorings | I16: CSMOORING | J16: WQ Sensor | K16: 8 | L16: Ongoing | M16: 2023 | O16: Y | P16: Data Lake | Q16: High | U16: data in data lake is incomplete (date range). One site has duplicate variable name that need to be dealt with when import
A17: 17 | B17: Data | C17: Knowledge | D17: Private | E17: State Programs | F17: Department of Water and Environmental Regulation | G17: DWER | H17: Souther Metropolitan Coastal Waters (1990) | I17: EPA-SMCW | L17: Fixed | O17: N | P17: Action Required | Q17: Medium
A18: 18 | B18: Data | C18: Validation-WQ | D18: Private | E18: Local Provider | F18: Fremantle Ports Authority | G18: FPA | H18: FPA WQ Sampling | I18: FPAWQ | J18: WQ Grab | K18: 14 | L18: Ongoing | O18: Y | P18: Action Required | Q18: High
A19: 19 | B19: Data | C19: Validation-Hydro | D19: Private | E19: Local Provider | F19: Fremantle Ports Authority | G19: FPA | H19: FPA ADCP | I19: FPAADCP | J19: HYDRO Sensor | K19: 2 | L19: Ongoing | O19: Y | P19: Action Required | Q19: High | S19: Unsure… if mapped all sites, or if these sites refer to another program
A20: 20 | B20: Data | C20: Validation-WQ | D20: Private | E20: Local Provider | F20: Fremantle Ports Authority | G20: FPA | H20: Fremantle Bulk Terminal | I20: FBT-WQ | J20: WQ Grab | K20: 1 | L20: Ongoing | O20: N | P20: Action Required | Q20: High
A21: 21 | B21: Data | C21: Validation-WQ | D21: Private | E21: Local Provider | F21: Fremantle Ports Authority | G21: FPA | H21: Fremantle Bulk Jetty | I21: FBJ-WQ | J21: WQ Grab | K21: 1 | L21: Ongoing | O21: N | P21: Action Required | Q21: High
A22: 22 | B22: Data | C22: Validation-Hydro | D22: Public | E22: National Facilities | F22: Integrated Marine Observing System | G22: IMOS | H22: AMNM Mooring | I22: AMNMMOORING | J22: HYDRO Sensor | K22: 7 | L22: Ongoing | O22: y | P22: Data Warehouse | Q22: High
A23: 23 | B23: Data | C23: Validation-WQ | D23: Public | E23: National Facilities | F23: Integrated Marine Observing System | G23: IMOS | H23: BGC | I23: BGC | J23: WQ Grab | K23: # | L23: Ongoing | O23: Y | P23: Data Warehouse | Q23: High
A24: 24 | B24: Data | C24: Validation-WQ | D24: Public | E24: National Facilities | F24: Integrated Marine Observing System | G24: IMOS | H24: ANMN Burst/Profiles | I24: AMNMProfile | J24: WQ Profile | K24: # | L24: Ongoing | O24: y | P24: Data Warehouse | Q24: High
A25: 25 | B25: Data | C25: Validation-Sed | D25: Private | E25: Local Provider | F25: Tronox Kwinana Pigment Plant | G25: TKPP | H25: Tronox Kwinana Pigment Plant | I25: TKPP-WQ | J25: SED Grab | K25: 1 | L25: Ongoing | M25: 2018 | O25: N | P25: Data Lake | Q25: Medium | U25: datasets on Sharepoint but can't find in data lake on CSIEM drive
A26: 26 | B26: Data | C26: Validation-WQ | D26: Private | E26: Local Provider | F26: University of Western Australia | G26: UWA | H26: CWR studies | I26: CWR | J26: WQ Sensor; HYDRO Sensor | K26: # | L26: Fixed | O26: N | P26: Action Required | Q26: Low
A27: 27 | B27: Data | C27: Validation-WQ | D27: Private | E27: Local Provider | F27: University of Western Australia | G27: UWA | H27: SCEVO | I27: AED | J27: WQ Grab;WQ Sensor;WQ Profile;HYDRO Flow | K27: # | L27: Ongoing | O27: N | P27: Action Required | Q27: Low
A28: 28 | B28: Data | C28: Validation-WQ | D28: Private | E28: Local Provider | F28: University of Western Australia | G28: UWA | H28: CWR CTD Profiling | I28: CWRCTD | J28: WQ Sensor | K28: # | L28: Ongoing | O28: Y | P28: Data Lake | Q28: Low
A29: 29 | B29: Data | C29: Validation-WQ | D29: Private | E29: Local Provider | F29: University of Western Australia | G29: UWA | H29: GK-PAR | I29: GK-PAR | J29: WQ Sensor | K29: 1 | L29: Ongoing | O29: N | P29: Data Lake | Q29: Medium
A30: 30 | B30: Data | C30: Validation-WQ | D30: Private | E30: State Programs | F30: Western Australian Marine Science Institution | G30: WAMSI | H30: WAMSI Westport Marine Science Program | I30: WWMSP5.1 | J30: WQ Sensor; HYDRO Sensor; HYDRO Level | K30: 7 | L30: Fixed | O30: Y | P30: Data Warehouse | Q30: High
A31: 31 | B31: Data | C31: Validation-WQ | D31: Private | E31: State Programs | F31: Western Australian Marine Science Institution | G31: WAMSI | H31: WAMSI Westport Marine Science Program | I31: WWMSP3 | J31: WQ Grab | K31: 18 | L31: Ongoing | O31: Y | P31: Data Lake | Q31: High | S31: Needs review, but should be removed
A32: 32 | B32: Data | C32: Validation-WQ | D32: Private | E32: State Programs | F32: Western Australian Marine Science Institution | G32: WAMSI | H32: WAMSI Westport Marine Science Program | I32: WWMSP3.1 | J32: WQ Sensor | K32: 18 | L32: Ongoing | P32: Data Lake | Q32: High
A33: 33 | B33: Data | C33: Knowledge | D33: Private | E33: State Agencies | F33: Water Corporation | G33: WC | H33: Perth Coastal Waters 1995 | L33: Ongoing | O33: N | P33: Action Required | Q33: Medium
A34: 34 | B34: Data | C34: Validation-WQ | D34: Private | E34: State Agencies | F34: Water Corporation | G34: WC | H34: Perth Long-Term Ocean Outlet Monitoring | I34: PLOOM | J34: WQ Grab | L34: Ongoing | M34: 2008 | O34: Y | P34: Action Required | Q34: High | S34: Unsure… if mapped all sites, or if these sites refer to another program
A35: 35 | B35: Data | C35: Validation-WQ | D35: Private | E35: State Agencies | F35: Water Corporation | G35: WC | H35: Sepia Depression Ocean Outlet Landline | I35: SDOOL | J35: WQ Grab | K35: 32 | L35: Ongoing | O35: y | P35: Action Required | Q35: High
A36: 36 | B36: Data | C36: Validation-Hydro | D36: Private | E36: State Agencies | F36: Water Corporation | G36: WC | H36: Sepia Depression Ocean Outlet Landline | I36: SDOOL-FLOW | J36: HYDRO Flow | L36: Ongoing | O36: N | P36: Action Required | Q36: High
A37: 37 | B37: Data | C37: Validation-WQ | D37: Private | E37: State Agencies | F37: Water Corporation | G37: WC | H37: Perth Seawater Desalination Plant | I37: PSDP-SCADA | J37: WQ Sensor | K37: 1 | L37: Ongoing | M37: 2007 | O37: N | P37: Action Required | Q37: High
A38: 38 | B38: Data | C38: Validation-Hydro | D38: Private | E38: State Agencies | F38: Water Corporation | G38: WC | H38: Perth Seawater Desalination Plant | I38: PSDP-BRINE | J38: HYDRO Sensor | K38: 1 | L38: Ongoing | O38: N | P38: Action Required | Q38: High
A39: 39 | B39: Data | C39: Groundwater | D39: Private | E39: Local Provider | F39: Coogee Chemicals | G39: CC | H39: Coogee Chemicals | I39: CC | J39: WQ Grab | K39: 8 | L39: Fixed | M39: 2022 | O39: N | P39: Action Required | Q39: low | U39: site locations unclear
A40: 40 | B40: Data | C40: Bathymetry | D40: Public | E40: State Agencies | F40: Department of Defence | G40: DOD | H40: Cockburn Sound Profile Monitoring | I40: CSPM | J40: Beach profile | L40: Fixed | M40: 2003 | O40: N | P40: Action Required | Q40: low
...

Sheet Meteorology
A1: row# | B1: Table | C1: CSIEM Category | D1: Ownership | E1: Group | F1: Agency / Organisation | G1: Agency ID | H1: Program | I1: Program Code | J1: Data Classification | K1: No of Sites | L1: Timing | M1: Date Last Updated | N1: Date Range | O1: Sites Mapped | P1: Import Status | Q1: Priority | R1: Science Review | S1: Notes | T1: Link / Reference | U1: Notes_SZ
A2: {=_xlfn._xlws.FILTER('CATALOGUE (old)'!A:A,'CATALOGUE (old)'!$C:$C="Weather","")} -> 2 | B2: {=_xlfn._xlws.FILTER('CATALOGUE (old)'!B:B,'CATALOGUE (old)'!$C:$C="Weather","")} -> Data | C2: {=_xlfn._xlws.FILTER('CATALOGUE (old)'!C:C,'CATALOGUE (old)'!$C:$C="Weather","")} -> Weather | D2: {=_xlfn._xlws.FILTER('CATALOGUE (old)'!D:D,'CATALOGUE (old)'!$C:$C="Weather","")} -> Public | E2: {=_xlfn._xlws.FILTER('CATALOGUE (old)'!E:E,'CATALOGUE (old)'!$C:$C="Weather","")} -> National Facilities | F2: {=_xlfn._xlws.FILTER('CATALOGUE (old)'!F:F,'CATALOGUE (old)'!$C:$C="Weather","")} -> Bureau of Meteorology | G2: {=_xlfn._xlws.FILTER('CATALOGUE (old)'!G:G,'CATALOGUE (old)'!$C:$C="Weather","")} -> BOM | H2: {=_xlfn._xlws.FILTER('CATALOGUE (old)'!H:H,'CATALOGUE (old)'!$C:$C="Weather","")} -> Weather | I2: {=_xlfn._xlws.FILTER('CATALOGUE (old)'!I:I,'CATALOGUE (old)'!$C:$C="Weather","")} -> #VALUE! | J2: {=_xlfn._xlws.FILTER('CATALOGUE (old)'!J:J,'CATALOGUE (old)'!$C:$C="Weather","")} -> MET General | K2: {=_xlfn._xlws.FILTER('CATALOGUE (old)'!K:K,'CATALOGUE (old)'!$C:$C="Weather","")} -> 16 | L2: {=_xlfn._xlws.FILTER('CATALOGUE (old)'!L:L,'CATALOGUE (old)'!$C:$C="Weather","")} -> Ongoing | M2: {=_xlfn._xlws.FILTER('CATALOGUE (old)'!M:M,'CATALOGUE (old)'!$C:$C="Weather","")} -> 0 | N2: {=_xlfn._xlws.FILTER('CATALOGUE (old)'!N:N,'CATALOGUE (old)'!$C:$C="Weather","")} -> 0 | O2: {=_xlfn._xlws.FILTER('CATALOGUE (old)'!O:O,'CATALOGUE (old)'!$C:$C="Weather","")} -> Y | P2: {=_xlfn._xlws.FILTER('CATALOGUE (old)'!P:P,'CATALOGUE (old)'!$C:$C="Weather","")} -> Data Warehouse | Q2: {=_xlfn._xlws.FILTER('CATALOGUE (old)'!Q:Q,'CATALOGUE (old)'!$C:$C="Weather","")} -> High | R2: {=_xlfn._xlws.FILTER('CATALOGUE (old)'!R:R,'CATALOGUE (old)'!$C:$C="Weather","")} -> 0 | S2: {=_xlfn._xlws.FILTER('CATALOGUE (old)'!S:S,'CATALOGUE (old)'!$C:$C="Weather","")} -> 0 | T2: {=_xlfn._xlws.FILTER('CATALOGUE (old)'!T:T,'CATALOGUE (old)'!$C:$C="Weather","")} -> 0 | U2: {=_xlfn._xlws.FILTER('CATALOGUE (old)'!U:U,'CATALOGUE (old)'!$C:$C="Weather","")} -> 0
A3: 3 | B3: Data | C3: Weather | D3: Public | E3: National Facilities | F3: Bureau of Meteorology | G3: BOM | H3: Australian Baseline Sea Level Monitoring Project | J3: HYDRO Level | K3: 1 | L3: Ongoing | M3: 0 | N3: 0 | O3: N | P3: Action Required | Q3: Low | R3: 0 | S3: 0 | T3: 0 | U3: Site: Hillarys. See 'waves' sheet
A4: 11 | B4: Data | C4: Weather | D4: Public | E4: State Agencies | F4: Department of Primary Industries and Regional Development | G4: DPIRD | H4: Automatic Weather Stations | J4: MET General | K4: # | L4: Ongoing | M4: 0 | N4: 0 | O4: N | P4: Action Required | Q4: Medium | R4: 0 | S4: 0 | T4: 0 | U4: 0
A5: 42 | B5: Data | C5: Weather | D5: Public | E5: State Agencies | F5: Department of Transport | G5: DOT | H5: Coastal Data | J5: HYDRO Level | K5: 1 | L5: Ongoing | M5: 2023 | N5: 0 | O5: N | P5: Action Required | Q5: High | R5: 0 | S5: 0 | T5: 0 | U5: need to check if this is included in row 10
A6: 76 | B6: Data | C6: Weather | D6: Private | E6: State Agencies | F6: Water Corporation | G6: WC | H6: Metocean Summary Report | J6: MET General | K6: 4 | L6: 0 | M6: 2018 | N6: 0 | O6: 0 | P6: 0 | Q6: 0 | R6: 0 | S6: 0 | T6: 0 | U6: 0

Sheet WQ - Sensor
A1: WQ
A14: Variable | B14: Site | C14: Source | D14: Report page | E14: Data location | H14: Data catalogue
A15: velocity (multiple layers) | B15: S01, S02 | C15: JPPL-AWAC | D15: 39-42 | E15: \AED Dropbox\AED_Cockburn_db\3_data\Data\JPPL\JPPL_AWAC; (12/2012 - 12/2013) | H15: row 85
A16: water level | B16: Stirling, Parmelia, Northmole | C16: FPA | D16: 46 | E16: 2011-2021 on Sharepoint, .mat file 2011-2016 on CSIEM-Marvl from BMT (no northmole) | H16: row 50 and 87
A17: temp, salinity, velocity (surface, middle, bottom) | B17: Northern, Central and Southern Buoys ,MMMP (21 sites) | C17: WC | D17: 48, 54 | E17: bmt compiled .mat (1/2013-1/6/2013), but no MMMP - MMMP may be the same as PSDP??? | H17: row 88
A18: temp, salinity, velocity, H (surface, bottom) | B18: PSDP (21 sites grouped into inner, middle radii, outer) | C18: WC | D18: 49-51, 55-57 | E18: not avail from bmt .mat | H18: row 89
A19: temp, salinity, velocity, H | B19: Northern basin, spoil grounds, western power | C19: FPA | D19: NA | E19: bmt compliled .mat file (2013) but not in report | G19: refer to report: BMT desalination plant discharge modelling | H19: row 90
A20: temp, salinity (profile) | B20: Central buoy, MMMP (21 sites) | C20: WC | D20: 52-53, 58-59 | E20: not avail from bmt .mat | H20: row 91
A21: TSS | B21: CS6A, CS7, CS11, MB | C21: CSMC | D21: 70 | E21: U:\data-lake\csmc\csmcwq-mafrl, also in .mat from bmt 2012- 3/2015 | H21: row 8
A22: temp, salinity, TSS, DO, DO sat, TN, TP, AMM, NIT, FRP, ChlA surface/bottom | B22: 14 sites (CS5, CS4,..) | C22: CSMC | D22: 80-112 | E22: U:\data-lake\csmc\csmcwq-mafrl, not avail from bmt .mat | H22: row 8
A23: DO (surface, bottom) | B23: Northern, Central and Southern Buoys | C23: WC | D23: 114 | E23: not avail from bmt .mat | H23: row 92
A24: DO (surface, bottom) | B24: PSDP (21 sites grouped into inner, middle radii, outer) | C24: WC | D24: 115 | E24: not avail from bmt .mat | H24: row 89
A25: DO (profile) | B25: Central buoy, MMMP (21 sites) | C25: WC | D25: 118-119 | E25: not avail from bmt .mat | H25: row 91

Sheet WQ - Profile Grab

Sheet Water Quality
A1: row# | B1: Table | C1: CSIEM Category | D1: Ownership | E1: Group | F1: Agency / Organisation | G1: Agency ID | H1: Program | I1: Program Code | J1: Data Classification | K1: No of Sites | L1: Timing | M1: Date Last Updated | N1: Date Range | O1: Sites Mapped | P1: Import Status | Q1: Priority | R1: Science Review | S1: Notes | T1: Link / Reference | U1: Notes_SZ
